Workbook

Sheet Assessment
A1: * กรอกเลขลำดับของนักศึกษาใน Column D >> ขอให้อาจารย์แจ้งนักศึกษาตรวจสอบเลขบัตรประชาชนด้วยครับ รอบนี้จะโอนเงินผ่านระบบ Promtpay เข้าบัญชีที่ผูกกับเลขบัตรประชาชน | D1: กรอกหมายเลขลำดับนักศึกษาในช่องนี้ | E1: รหัส | F1: ชื่อ - สกุล | G1: ค่าเทอม | I1: ค่าใช้จ่ายประจำวัน | K1: ทำงานพิเศษ | M1: การนำทุนไปใช้ประโยชน์ | O1: ค่าใช้จ่ายประจำวัน | Q1: ค่าที่พัก (ค่าเช่า ค่าน้ำ ค่าไฟ) | S1: การเดินทางมาเรียน | U1: ผลการเรียน | W1: ดุลพินิจของอาจารย์ (0-10) *สามารถระบุเป็นคะแนนอื่นๆได้ | Y1: ส่วนร่วมกับคณะหรือมหาวิทยาลัย | AA1: รวมคะแนนทั้งสิ้น | AB1: การรับทุนต่อเนื่อง 2 ภาคการศึกษา | AC1: มูลค่าทุนที่สมควรได้รับ *สามารถระบุเป็นค่าอื่นๆได้ | AD1: ความเห็นเพิ่มเติม
A2: {=IF(INDEX(D:D,MATCH(99999,D:D))="","",VLOOKUP(INDEX(D:D,MATCH(99999,D:D)),รายชื่อผู้สมัคร!$A$2:$H$99874,2,FALSE))} -> 683040000-4 | B2: {=IF(INDEX(D:D,MATCH(99999,D:D))="","",(VLOOKUP(INDEX(D:D,MATCH(99999,D:D)),รายชื่อผู้สมัคร!$A$2:$H$9874,4,FALSE) & " " & VLOOKUP(INDEX(D:D,MATCH(99999,D:D)),รายชื่อผู้สมัคร!$A$2:$H$99874,5,FALSE) & " " & VLOOKUP(INDEX(D:D,MATCH(99999,D:D)),รายชื่อผู้สมัคร!$A$2:$H$9874,6,FALSE)))} -> นางสาว ddd dddd | D2: 1 | E2: =IF($D2="","",VLOOKUP($D2,รายชื่อผู้สมัคร!$A$4:$H$224,2,FALSE)) -> 683040000-1 | F2: =IF($D2="","",(VLOOKUP($D2,รายชื่อผู้สมัคร!$A$4:$H$99,4,FALSE) & " " & VLOOKUP($D2,รายชื่อผู้สมัคร!$A$4:$H$99,5,FALSE) & " " & VLOOKUP($D2,รายชื่อผู้สมัคร!$A$4:$H$99,6,FALSE))) -> นาย aaa aaaa | G2: ไม่มีผู้อื่นส่งเสียค่าเทอม | H2: =IF(G2="","",VLOOKUP(G2,Criteria!$D$2:$E$5,2,FALSE)) -> 10 | I2: มีผู้อื่นหรือแหล่งทุนอื่นส่งเสียค่าใช้จ่ายประจำวัน แต่ไม่เพียงพอ หรือได้รับจากการกู้ยืม | J2: =IF(I2="","",VLOOKUP(I2,Criteria!$D$6:$E$9,2,FALSE)) -> 5 | K2: ปัจจุบันทำงานหาเลี้ยงตนเอง หรือทำงานที่ไม่ได้มีรายรับ | L2: =IF(K2="","",VLOOKUP(K2,Criteria!$D$10:$E$13,2,FALSE)) -> 10 | M2: ใช้เป็นค่าเทอม หรือค่าใช้จ่ายประจำวัน | N2: =IF(M2="","",VLOOKUP(M2,Criteria!$D$14:$E$21,2,FALSE)) -> 20 | O2: ≤ 5,000 บาท ต่อเดือน | P2: =IF(O2="","",VLOOKUP(O2,Criteria!$D$22:$E$25,2,FALSE)) -> 10 | Q2: พักอยู่กับครอบครัว ญาติ หรือ ค่าที่พักอยู่ระหว่าง 2001-4000 บาท | R2: =IF(Q2="","",VLOOKUP(Q2,Criteria!$D$26:$E$29,2,FALSE)) -> 5 | S2: รถสาธารณะ/รถจักรยาน/เดิน/ติดรถผู้อื่นมา | T2: =IF(S2="","",VLOOKUP(S2,Criteria!$D$30:$E$33,2,FALSE)) -> 5 | U2: 3.00 ขึ้นไป | V2: =IF(U2="","",VLOOKUP(U2,Criteria!$D$34:$E$38,2,FALSE)) -> 5 | W2: จำเป็นอื่นๆตามความเห็นอาจารย์ | X2: =IF(W2="","",VLOOKUP(W2,Criteria!$D$39:$E$42,2,FALSE)) -> 5 | Y2: - | Z2: 0 | AA2: =SUM(H2,J2,L2,N2,P2,R2,T2,V2,X2,Z2) -> 75 | AB2: สมควรได้รับทุนต่อเนื่อง 2 ภาคการศึกษา | AC2: 20000 | AD2: เก็บข้อมูลไว้รับทุนต่อเนื่องของสมาคมได้
A3: เลขบัตรประชาชน | B3: =VLOOKUP($A$2,Data!$B$2:$AL$99874,37,FALSE) -> 1410100000004 | D3: 2 | F3: =IF($D3="","",(VLOOKUP($D3,รายชื่อผู้สมัคร!$A$4:$H$99,4,FALSE) & " " & VLOOKUP($D3,รายชื่อผู้สมัคร!$A$4:$H$99,5,FALSE) & " " & VLOOKUP($D3,รายชื่อผู้สมัคร!$A$4:$H$99,6,FALSE))) -> นาย bbb vvvv | G3: มีผู้อื่นหรือแหล่งทุนอื่นส่งเสียค่าเทอมบางส่วน หรือกู้ยืม หรือกู้ กยศ ไม่ผ่าน | H3: =IF(G3="","",VLOOKUP(G3,Criteria!$D$2:$E$5,2,FALSE)) -> 5 | I3: มีผู้อื่นหรือแหล่งทุนอื่นส่งเสียค่าใช้จ่ายประจำวัน แต่ไม่เพียงพอ หรือได้รับจากการกู้ยืม | J3: =IF(I3="","",VLOOKUP(I3,Criteria!$D$6:$E$9,2,FALSE)) -> 5 | K3: ไม่ทำงานหาเลี้ยงตนเอง | L3: =IF(K3="","",VLOOKUP(K3,Criteria!$D$10:$E$13,2,FALSE)) -> 0 | M3: เงินสะสมฉุกเฉิน หรือ ไม่อยากรบกวนครอบครัว | N3: =IF(M3="","",VLOOKUP(M3,Criteria!$D$14:$E$21,2,FALSE)) -> 5 | O3: ≤ 5,000 บาท ต่อเดือน | P3: =IF(O3="","",VLOOKUP(O3,Criteria!$D$22:$E$25,2,FALSE)) -> 10 | Q3: พักอยู่กับครอบครัว ญาติ หรือ ค่าที่พักอยู่ระหว่าง 2001-4000 บาท | R3: =IF(Q3="","",VLOOKUP(Q3,Criteria!$D$26:$E$29,2,FALSE)) -> 5 | S3: รถมอเตอร์ไซค์ | T3: =IF(S3="","",VLOOKUP(S3,Criteria!$D$30:$E$33,2,FALSE)) -> 2 | U3: 3.00 ขึ้นไป | V3: =IF(U3="","",VLOOKUP(U3,Criteria!$D$34:$E$38,2,FALSE)) -> 5 | W3: จำเป็นอื่นๆตามความเห็นอาจารย์ | X3: =IF(W3="","",VLOOKUP(W3,Criteria!$D$39:$E$42,2,FALSE)) -> 5 | Y3: - | Z3: 0 | AA3: =SUM(H3,J3,L3,N3,P3,R3,T3,V3,X3,Z3) -> 42 | AB3: - | AC3: 5000
A4: สาขาวิชา | B4: =VLOOKUP($A$2,Data!$B$2:$AK$99874,6,FALSE) -> วิศวกรรมไฟฟ้า | D4: 3 | F4: =IF($D4="","",(VLOOKUP($D4,รายชื่อผู้สมัคร!$A$4:$H$99,4,FALSE) & " " & VLOOKUP($D4,รายชื่อผู้สมัคร!$A$4:$H$99,5,FALSE) & " " & VLOOKUP($D4,รายชื่อผู้สมัคร!$A$4:$H$99,6,FALSE))) -> นาย ccc cccc | G4: มีผู้อื่นหรือแหล่งทุนอื่นส่งเสียค่าเทอมบางส่วน หรือกู้ยืม หรือกู้ กยศ ไม่ผ่าน | H4: =IF(G4="","",VLOOKUP(G4,Criteria!$D$2:$E$5,2,FALSE)) -> 5 | I4: มีผู้อื่นหรือแหล่งทุนอื่นส่งเสียค่าใช้จ่ายประจำวัน แต่ไม่เพียงพอ หรือได้รับจากการกู้ยืม | J4: =IF(I4="","",VLOOKUP(I4,Criteria!$D$6:$E$9,2,FALSE)) -> 5 | K4: ไม่ทำงานหาเลี้ยงตนเอง | L4: =IF(K4="","",VLOOKUP(K4,Criteria!$D$10:$E$13,2,FALSE)) -> 0 | M4: เงินสะสมฉุกเฉิน หรือ ไม่อยากรบกวนครอบครัว | N4: =IF(M4="","",VLOOKUP(M4,Criteria!$D$14:$E$21,2,FALSE)) -> 5 | O4: ≤ 5,000 บาท ต่อเดือน | P4: =IF(O4="","",VLOOKUP(O4,Criteria!$D$22:$E$25,2,FALSE)) -> 10 | Q4: หอในมหาวิทยาลัย นอนวัด หรือ ค่าเช่าต่ำกว่า 2000 ต่อเดือน | R4: =IF(Q4="","",VLOOKUP(Q4,Criteria!$D$26:$E$29,2,FALSE)) -> 10 | S4: รถสาธารณะ/รถจักรยาน/เดิน/ติดรถผู้อื่นมา | T4: =IF(S4="","",VLOOKUP(S4,Criteria!$D$30:$E$33,2,FALSE)) -> 5 | U4: 3.00 ขึ้นไป | V4: =IF(U4="","",VLOOKUP(U4,Criteria!$D$34:$E$38,2,FALSE)) -> 5 | W4: จำเป็นอื่นๆตามความเห็นอาจารย์ | X4: =IF(W4="","",VLOOKUP(W4,Criteria!$D$39:$E$42,2,FALSE)) -> 5 | Y4: - | Z4: 5 | AA4: =SUM(H4,J4,L4,N4,P4,R4,T4,V4,X4,Z4) -> 55 | AB4: - | AC4: 20000
A5: ชั้นปี | B5: =VLOOKUP($A$2,Data!$B$2:$AK$99874,7,FALSE) -> 1 | D5: 4 | F5: =IF($D5="","",(VLOOKUP($D5,รายชื่อผู้สมัคร!$A$4:$H$99,4,FALSE) & " " & VLOOKUP($D5,รายชื่อผู้สมัคร!$A$4:$H$99,5,FALSE) & " " & VLOOKUP($D5,รายชื่อผู้สมัคร!$A$4:$H$99,6,FALSE))) -> นางสาว ddd dddd | G5: มีผู้อื่นหรือแหล่งทุนอื่นส่งเสียค่าเทอมบางส่วน หรือกู้ยืม หรือกู้ กยศ ไม่ผ่าน | H5: =IF(G5="","",VLOOKUP(G5,Criteria!$D$2:$E$5,2,FALSE)) -> 5 | I5: มีผู้อื่นหรือแหล่งทุนอื่นส่งเสียค่าใช้จ่ายประจำวัน แต่ไม่เพียงพอ หรือได้รับจากการกู้ยืม | J5: =IF(I5="","",VLOOKUP(I5,Criteria!$D$6:$E$9,2,FALSE)) -> 5 | K5: ไม่ทำงานหาเลี้ยงตนเอง | L5: =IF(K5="","",VLOOKUP(K5,Criteria!$D$10:$E$13,2,FALSE)) -> 0 | M5: เงินสะสมฉุกเฉิน หรือ ไม่อยากรบกวนครอบครัว | N5: =IF(M5="","",VLOOKUP(M5,Criteria!$D$14:$E$21,2,FALSE)) -> 5 | O5: ≤ 5,000 บาท ต่อเดือน | P5: =IF(O5="","",VLOOKUP(O5,Criteria!$D$22:$E$25,2,FALSE)) -> 10 | Q5: หอในมหาวิทยาลัย นอนวัด หรือ ค่าเช่าต่ำกว่า 2000 ต่อเดือน | R5: =IF(Q5="","",VLOOKUP(Q5,Criteria!$D$26:$E$29,2,FALSE)) -> 10 | S5: รถสาธารณะ/รถจักรยาน/เดิน/ติดรถผู้อื่นมา | T5: =IF(S5="","",VLOOKUP(S5,Criteria!$D$30:$E$33,2,FALSE)) -> 5 | U5: 2.50-2.99 | V5: =IF(U5="","",VLOOKUP(U5,Criteria!$D$34:$E$38,2,FALSE)) -> 3 | W5: ไม่จำเป็น | X5: =IF(W5="","",VLOOKUP(W5,Criteria!$D$39:$E$42,2,FALSE)) -> 0 | Y5: - | Z5: 0 | AA5: =SUM(H5,J5,L5,N5,P5,R5,T5,V5,X5,Z5) -> 43 | AB5: - | AC5: 5000
A6: ที่พัก | B6: =VLOOKUP($A$2,Data!$B$2:$AK$99874,12,FALSE) -> อื่นๆ | E6: =IF($D6="","",VLOOKUP($D6,รายชื่อผู้สมัคร!$A$4:$H$99,2,FALSE)) | F6: =IF($D6="","",(VLOOKUP($D6,รายชื่อผู้สมัคร!$A$4:$H$99,4,FALSE) & " " & VLOOKUP($D6,รายชื่อผู้สมัคร!$A$4:$H$99,5,FALSE) & " " & VLOOKUP($D6,รายชื่อผู้สมัคร!$A$4:$H$99,6,FALSE))) | G6: - | H6: =IF(G6="","",VLOOKUP(G6,Criteria!$D$2:$E$5,2,FALSE)) -> - | I6: - | J6: =IF(I6="","",VLOOKUP(I6,Criteria!$D$6:$E$9,2,FALSE)) -> - | K6: - | L6: =IF(K6="","",VLOOKUP(K6,Criteria!$D$10:$E$13,2,FALSE)) -> - | M6: - | N6: =IF(M6="","",VLOOKUP(M6,Criteria!$D$14:$E$21,2,FALSE)) -> - | O6: - | P6: =IF(O6="","",VLOOKUP(O6,Criteria!$D$22:$E$25,2,FALSE)) -> - | Q6: - | R6: =IF(Q6="","",VLOOKUP(Q6,Criteria!$D$26:$E$29,2,FALSE)) -> - | S6: - | T6: =IF(S6="","",VLOOKUP(S6,Criteria!$D$30:$E$33,2,FALSE)) -> - | U6: - | V6: =IF(U6="","",VLOOKUP(U6,Criteria!$D$34:$E$38,2,FALSE)) -> - | W6: - | X6: =IF(W6="","",VLOOKUP(W6,Criteria!$D$39:$E$42,2,FALSE)) -> - | Y6: - | Z6: =IF(Y6="","",VLOOKUP(Y6,Criteria!$D$43:$E$44,2,FALSE)) -> - | AA6: =SUM(H6,J6,L6,N6,P6,R6,T6,V6,X6,Z6) -> 0 | AB6: - | AC6: -
A7: ค่าเช่าหอ/บ้าน รวมค่าน้ำ-ไฟ | B7: =VLOOKUP($A$2,Data!$B$2:$AK$99874,13,FALSE) -> 2200 | E7: =IF($D7="","",VLOOKUP($D7,รายชื่อผู้สมัคร!$A$4:$H$99,2,FALSE)) | F7: =IF($D7="","",(VLOOKUP($D7,รายชื่อผู้สมัคร!$A$4:$H$99,4,FALSE) & " " & VLOOKUP($D7,รายชื่อผู้สมัคร!$A$4:$H$99,5,FALSE) & " " & VLOOKUP($D7,รายชื่อผู้สมัคร!$A$4:$H$99,6,FALSE))) | G7: - | H7: =IF(G7="","",VLOOKUP(G7,Criteria!$D$2:$E$5,2,FALSE)) -> - | I7: - | J7: =IF(I7="","",VLOOKUP(I7,Criteria!$D$6:$E$9,2,FALSE)) -> - | K7: - | L7: =IF(K7="","",VLOOKUP(K7,Criteria!$D$10:$E$13,2,FALSE)) -> - | M7: - | N7: =IF(M7="","",VLOOKUP(M7,Criteria!$D$14:$E$21,2,FALSE)) -> - | O7: - | P7: =IF(O7="","",VLOOKUP(O7,Criteria!$D$22:$E$25,2,FALSE)) -> - | Q7: - | R7: =IF(Q7="","",VLOOKUP(Q7,Criteria!$D$26:$E$29,2,FALSE)) -> - | S7: - | T7: =IF(S7="","",VLOOKUP(S7,Criteria!$D$30:$E$33,2,FALSE)) -> - | U7: - | V7: =IF(U7="","",VLOOKUP(U7,Criteria!$D$34:$E$38,2,FALSE)) -> - | W7: - | X7: =IF(W7="","",VLOOKUP(W7,Criteria!$D$39:$E$42,2,FALSE)) -> - | Y7: - | Z7: =IF(Y7="","",VLOOKUP(Y7,Criteria!$D$43:$E$44,2,FALSE)) -> - | AA7: =SUM(H7,J7,L7,N7,P7,R7,T7,V7,X7,Z7) -> 0 | AB7: - | AC7: -
A8: ค่าใช้จ่ายส่วนตัว | B8: =VLOOKUP($A$2,Data!$B$2:$AK$99874,14,FALSE) -> 3500 | E8: =IF($D8="","",VLOOKUP($D8,รายชื่อผู้สมัคร!$A$4:$H$99,2,FALSE)) | F8: =IF($D8="","",(VLOOKUP($D8,รายชื่อผู้สมัคร!$A$4:$H$99,4,FALSE) & " " & VLOOKUP($D8,รายชื่อผู้สมัคร!$A$4:$H$99,5,FALSE) & " " & VLOOKUP($D8,รายชื่อผู้สมัคร!$A$4:$H$99,6,FALSE))) | G8: - | H8: =IF(G8="","",VLOOKUP(G8,Criteria!$D$2:$E$5,2,FALSE)) -> - | I8: - | J8: =IF(I8="","",VLOOKUP(I8,Criteria!$D$6:$E$9,2,FALSE)) -> - | K8: - | L8: =IF(K8="","",VLOOKUP(K8,Criteria!$D$10:$E$13,2,FALSE)) -> - | M8: - | N8: =IF(M8="","",VLOOKUP(M8,Criteria!$D$14:$E$21,2,FALSE)) -> - | O8: - | P8: =IF(O8="","",VLOOKUP(O8,Criteria!$D$22:$E$25,2,FALSE)) -> - | Q8: - | R8: =IF(Q8="","",VLOOKUP(Q8,Criteria!$D$26:$E$29,2,FALSE)) -> - | S8: - | T8: =IF(S8="","",VLOOKUP(S8,Criteria!$D$30:$E$33,2,FALSE)) -> - | U8: - | V8: =IF(U8="","",VLOOKUP(U8,Criteria!$D$34:$E$38,2,FALSE)) -> - | W8: - | X8: =IF(W8="","",VLOOKUP(W8,Criteria!$D$39:$E$42,2,FALSE)) -> - | Y8: - | Z8: =IF(Y8="","",VLOOKUP(Y8,Criteria!$D$43:$E$44,2,FALSE)) -> - | AA8: =SUM(H8,J8,L8,N8,P8,R8,T8,V8,X8,Z8) -> 0 | AB8: - | AC8: -
A9: ค่าอุปกรณ์การศึกษา | B9: =VLOOKUP($A$2,Data!$B$2:$AK$99874,15,FALSE) -> 500 | E9: =IF($D9="","",VLOOKUP($D9,รายชื่อผู้สมัคร!$A$4:$H$99,2,FALSE)) | F9: =IF($D9="","",(VLOOKUP($D9,รายชื่อผู้สมัคร!$A$4:$H$99,4,FALSE) & " " & VLOOKUP($D9,รายชื่อผู้สมัคร!$A$4:$H$99,5,FALSE) & " " & VLOOKUP($D9,รายชื่อผู้สมัคร!$A$4:$H$99,6,FALSE))) | G9: - | H9: =IF(G9="","",VLOOKUP(G9,Criteria!$D$2:$E$5,2,FALSE)) -> - | I9: - | J9: =IF(I9="","",VLOOKUP(I9,Criteria!$D$6:$E$9,2,FALSE)) -> - | K9: - | L9: =IF(K9="","",VLOOKUP(K9,Criteria!$D$10:$E$13,2,FALSE)) -> - | M9: - | N9: =IF(M9="","",VLOOKUP(M9,Criteria!$D$14:$E$21,2,FALSE)) -> - | O9: - | P9: =IF(O9="","",VLOOKUP(O9,Criteria!$D$22:$E$25,2,FALSE)) -> - | Q9: - | R9: =IF(Q9="","",VLOOKUP(Q9,Criteria!$D$26:$E$29,2,FALSE)) -> - | S9: - | T9: =IF(S9="","",VLOOKUP(S9,Criteria!$D$30:$E$33,2,FALSE)) -> - | U9: - | V9: =IF(U9="","",VLOOKUP(U9,Criteria!$D$34:$E$38,2,FALSE)) -> - | W9: - | X9: =IF(W9="","",VLOOKUP(W9,Criteria!$D$39:$E$42,2,FALSE)) -> - | Y9: - | Z9: =IF(Y9="","",VLOOKUP(Y9,Criteria!$D$43:$E$44,2,FALSE)) -> - | AA9: =SUM(H9,J9,L9,N9,P9,R9,T9,V9,X9,Z9) -> 0 | AB9: - | AC9: -
A10: อุปกรณ์อิเล็กทรอนิกส์ที่มี | B10: =VLOOKUP($A$2,Data!$B$2:$AK$99874,16,FALSE) -> โทรศัพท์, iPad | E10: =IF($D10="","",VLOOKUP($D10,รายชื่อผู้สมัคร!$A$4:$H$99,2,FALSE)) | F10: =IF($D10="","",(VLOOKUP($D10,รายชื่อผู้สมัคร!$A$4:$H$99,4,FALSE) & " " & VLOOKUP($D10,รายชื่อผู้สมัคร!$A$4:$H$99,5,FALSE) & " " & VLOOKUP($D10,รายชื่อผู้สมัคร!$A$4:$H$99,6,FALSE))) | G10: - | H10: =IF(G10="","",VLOOKUP(G10,Criteria!$D$2:$E$5,2,FALSE)) -> - | I10: - | J10: =IF(I10="","",VLOOKUP(I10,Criteria!$D$6:$E$9,2,FALSE)) -> - | K10: - | L10: =IF(K10="","",VLOOKUP(K10,Criteria!$D$10:$E$13,2,FALSE)) -> - | M10: - | N10: =IF(M10="","",VLOOKUP(M10,Criteria!$D$14:$E$21,2,FALSE)) -> - | O10: - | P10: =IF(O10="","",VLOOKUP(O10,Criteria!$D$22:$E$25,2,FALSE)) -> - | Q10: - | R10: =IF(Q10="","",VLOOKUP(Q10,Criteria!$D$26:$E$29,2,FALSE)) -> - | S10: - | T10: =IF(S10="","",VLOOKUP(S10,Criteria!$D$30:$E$33,2,FALSE)) -> - | U10: - | V10: =IF(U10="","",VLOOKUP(U10,Criteria!$D$34:$E$38,2,FALSE)) -> - | W10: - | X10: =IF(W10="","",VLOOKUP(W10,Criteria!$D$39:$E$42,2,FALSE)) -> - | Y10: - | Z10: =IF(Y10="","",VLOOKUP(Y10,Criteria!$D$43:$E$44,2,FALSE)) -> - | AA10: =SUM(H10,J10,L10,N10,P10,R10,T10,V10,X10,Z10) -> 0 | AB10: - | AC10: -
A11: รายได้เสริม | B11: =VLOOKUP($A$2,Data!$B$2:$AK$99874,17,FALSE) -> มีรายได้เสริม | E11: =IF($D11="","",VLOOKUP($D11,รายชื่อผู้สมัคร!$A$4:$H$99,2,FALSE)) | F11: =IF($D11="","",(VLOOKUP($D11,รายชื่อผู้สมัคร!$A$4:$H$99,4,FALSE) & " " & VLOOKUP($D11,รายชื่อผู้สมัคร!$A$4:$H$99,5,FALSE) & " " & VLOOKUP($D11,รายชื่อผู้สมัคร!$A$4:$H$99,6,FALSE))) | G11: - | H11: =IF(G11="","",VLOOKUP(G11,Criteria!$D$2:$E$5,2,FALSE)) -> - | I11: - | J11: =IF(I11="","",VLOOKUP(I11,Criteria!$D$6:$E$9,2,FALSE)) -> - | K11: - | L11: =IF(K11="","",VLOOKUP(K11,Criteria!$D$10:$E$13,2,FALSE)) -> - | M11: - | N11: =IF(M11="","",VLOOKUP(M11,Criteria!$D$14:$E$21,2,FALSE)) -> - | O11: - | P11: =IF(O11="","",VLOOKUP(O11,Criteria!$D$22:$E$25,2,FALSE)) -> - | Q11: - | R11: =IF(Q11="","",VLOOKUP(Q11,Criteria!$D$26:$E$29,2,FALSE)) -> - | S11: - | T11: =IF(S11="","",VLOOKUP(S11,Criteria!$D$30:$E$33,2,FALSE)) -> - | U11: - | V11: =IF(U11="","",VLOOKUP(U11,Criteria!$D$34:$E$38,2,FALSE)) -> - | W11: - | X11: =IF(W11="","",VLOOKUP(W11,Criteria!$D$39:$E$42,2,FALSE)) -> - | Y11: - | Z11: =IF(Y11="","",VLOOKUP(Y11,Criteria!$D$43:$E$44,2,FALSE)) -> - | AA11: =SUM(H11,J11,L11,N11,P11,R11,T11,V11,X11,Z11) -> 0 | AB11: - | AC11: -
A12: บิดา อายุ | B12: =VLOOKUP($A$2,Data!$B$2:$AK$99874,18,FALSE) -> 71 | E12: =IF($D12="","",VLOOKUP($D12,รายชื่อผู้สมัคร!$A$4:$H$99,2,FALSE)) | F12: =IF($D12="","",(VLOOKUP($D12,รายชื่อผู้สมัคร!$A$4:$H$99,4,FALSE) & " " & VLOOKUP($D12,รายชื่อผู้สมัคร!$A$4:$H$99,5,FALSE) & " " & VLOOKUP($D12,รายชื่อผู้สมัคร!$A$4:$H$99,6,FALSE))) | G12: - | H12: =IF(G12="","",VLOOKUP(G12,Criteria!$D$2:$E$5,2,FALSE)) -> - | I12: - | J12: =IF(I12="","",VLOOKUP(I12,Criteria!$D$6:$E$9,2,FALSE)) -> - | K12: - | L12: =IF(K12="","",VLOOKUP(K12,Criteria!$D$10:$E$13,2,FALSE)) -> - | M12: - | N12: =IF(M12="","",VLOOKUP(M12,Criteria!$D$14:$E$21,2,FALSE)) -> - | O12: - | P12: =IF(O12="","",VLOOKUP(O12,Criteria!$D$22:$E$25,2,FALSE)) -> - | Q12: - | R12: =IF(Q12="","",VLOOKUP(Q12,Criteria!$D$26:$E$29,2,FALSE)) -> - | S12: - | T12: =IF(S12="","",VLOOKUP(S12,Criteria!$D$30:$E$33,2,FALSE)) -> - | U12: - | V12: =IF(U12="","",VLOOKUP(U12,Criteria!$D$34:$E$38,2,FALSE)) -> - | W12: - | X12: =IF(W12="","",VLOOKUP(W12,Criteria!$D$39:$E$42,2,FALSE)) -> - | Y12: - | Z12: =IF(Y12="","",VLOOKUP(Y12,Criteria!$D$43:$E$44,2,FALSE)) -> - | AA12: =SUM(H12,J12,L12,N12,P12,R12,T12,V12,X12,Z12) -> 0 | AB12: - | AC12: -
A13: บิดา อาชีพ | B13: =VLOOKUP($A$2,Data!$B$2:$AK$99874,19,FALSE) -> ไม่ได้ประกอบอาชีพ | E13: =IF($D13="","",VLOOKUP($D13,รายชื่อผู้สมัคร!$A$4:$H$99,2,FALSE)) | F13: =IF($D13="","",(VLOOKUP($D13,รายชื่อผู้สมัคร!$A$4:$H$99,4,FALSE) & " " & VLOOKUP($D13,รายชื่อผู้สมัคร!$A$4:$H$99,5,FALSE) & " " & VLOOKUP($D13,รายชื่อผู้สมัคร!$A$4:$H$99,6,FALSE))) | G13: - | H13: =IF(G13="","",VLOOKUP(G13,Criteria!$D$2:$E$5,2,FALSE)) -> - | I13: - | J13: =IF(I13="","",VLOOKUP(I13,Criteria!$D$6:$E$9,2,FALSE)) -> - | K13: - | L13: =IF(K13="","",VLOOKUP(K13,Criteria!$D$10:$E$13,2,FALSE)) -> - | M13: - | N13: =IF(M13="","",VLOOKUP(M13,Criteria!$D$14:$E$21,2,FALSE)) -> - | O13: - | P13: =IF(O13="","",VLOOKUP(O13,Criteria!$D$22:$E$25,2,FALSE)) -> - | Q13: - | R13: =IF(Q13="","",VLOOKUP(Q13,Criteria!$D$26:$E$29,2,FALSE)) -> - | S13: - | T13: =IF(S13="","",VLOOKUP(S13,Criteria!$D$30:$E$33,2,FALSE)) -> - | U13: - | V13: =IF(U13="","",VLOOKUP(U13,Criteria!$D$34:$E$38,2,FALSE)) -> - | W13: - | X13: =IF(W13="","",VLOOKUP(W13,Criteria!$D$39:$E$42,2,FALSE)) -> - | Y13: - | Z13: =IF(Y13="","",VLOOKUP(Y13,Criteria!$D$43:$E$44,2,FALSE)) -> - | AA13: =SUM(H13,J13,L13,N13,P13,R13,T13,V13,X13,Z13) -> 0 | AB13: - | AC13: -
A14: บิดา รายได้ | B14: =VLOOKUP($A$2,Data!$B$2:$AK$99874,20,FALSE) -> 0 | E14: =IF($D14="","",VLOOKUP($D14,รายชื่อผู้สมัคร!$A$4:$H$99,2,FALSE)) | F14: =IF($D14="","",(VLOOKUP($D14,รายชื่อผู้สมัคร!$A$4:$H$99,4,FALSE) & " " & VLOOKUP($D14,รายชื่อผู้สมัคร!$A$4:$H$99,5,FALSE) & " " & VLOOKUP($D14,รายชื่อผู้สมัคร!$A$4:$H$99,6,FALSE))) | G14: - | H14: =IF(G14="","",VLOOKUP(G14,Criteria!$D$2:$E$5,2,FALSE)) -> - | I14: - | J14: =IF(I14="","",VLOOKUP(I14,Criteria!$D$6:$E$9,2,FALSE)) -> - | K14: - | L14: =IF(K14="","",VLOOKUP(K14,Criteria!$D$10:$E$13,2,FALSE)) -> - | M14: - | N14: =IF(M14="","",VLOOKUP(M14,Criteria!$D$14:$E$21,2,FALSE)) -> - | O14: - | P14: =IF(O14="","",VLOOKUP(O14,Criteria!$D$22:$E$25,2,FALSE)) -> - | Q14: - | R14: =IF(Q14="","",VLOOKUP(Q14,Criteria!$D$26:$E$29,2,FALSE)) -> - | S14: - | T14: =IF(S14="","",VLOOKUP(S14,Criteria!$D$30:$E$33,2,FALSE)) -> - | U14: - | V14: =IF(U14="","",VLOOKUP(U14,Criteria!$D$34:$E$38,2,FALSE)) -> - | W14: - | X14: =IF(W14="","",VLOOKUP(W14,Criteria!$D$39:$E$42,2,FALSE)) -> - | Y14: - | Z14: =IF(Y14="","",VLOOKUP(Y14,Criteria!$D$43:$E$44,2,FALSE)) -> - | AA14: =SUM(H14,J14,L14,N14,P14,R14,T14,V14,X14,Z14) -> 0 | AB14: - | AC14: -
A15: บิดา สภาพ | B15: =VLOOKUP($A$2,Data!$B$2:$AK$99874,21,FALSE) -> มีชีวิตอยู่ | E15: =IF($D15="","",VLOOKUP($D15,รายชื่อผู้สมัคร!$A$4:$H$99,2,FALSE)) | F15: =IF($D15="","",(VLOOKUP($D15,รายชื่อผู้สมัคร!$A$4:$H$99,4,FALSE) & " " & VLOOKUP($D15,รายชื่อผู้สมัคร!$A$4:$H$99,5,FALSE) & " " & VLOOKUP($D15,รายชื่อผู้สมัคร!$A$4:$H$99,6,FALSE))) | G15: - | H15: =IF(G15="","",VLOOKUP(G15,Criteria!$D$2:$E$5,2,FALSE)) -> - | I15: - | J15: =IF(I15="","",VLOOKUP(I15,Criteria!$D$6:$E$9,2,FALSE)) -> - | K15: - | L15: =IF(K15="","",VLOOKUP(K15,Criteria!$D$10:$E$13,2,FALSE)) -> - | M15: - | N15: =IF(M15="","",VLOOKUP(M15,Criteria!$D$14:$E$21,2,FALSE)) -> - | O15: - | P15: =IF(O15="","",VLOOKUP(O15,Criteria!$D$22:$E$25,2,FALSE)) -> - | Q15: - | R15: =IF(Q15="","",VLOOKUP(Q15,Criteria!$D$26:$E$29,2,FALSE)) -> - | S15: - | T15: =IF(S15="","",VLOOKUP(S15,Criteria!$D$30:$E$33,2,FALSE)) -> - | U15: - | V15: =IF(U15="","",VLOOKUP(U15,Criteria!$D$34:$E$38,2,FALSE)) -> - | W15: - | X15: =IF(W15="","",VLOOKUP(W15,Criteria!$D$39:$E$42,2,FALSE)) -> - | Y15: - | Z15: =IF(Y15="","",VLOOKUP(Y15,Criteria!$D$43:$E$44,2,FALSE)) -> - | AA15: =SUM(H15,J15,L15,N15,P15,R15,T15,V15,X15,Z15) -> 0 | AB15: - | AC15: -
A16: มารดา อายุ | B16: =VLOOKUP($A$2,Data!$B$2:$AK$99874,22,FALSE) -> 54 | E16: =IF($D16="","",VLOOKUP($D16,รายชื่อผู้สมัคร!$A$4:$H$99,2,FALSE)) | F16: =IF($D16="","",(VLOOKUP($D16,รายชื่อผู้สมัคร!$A$4:$H$99,4,FALSE) & " " & VLOOKUP($D16,รายชื่อผู้สมัคร!$A$4:$H$99,5,FALSE) & " " & VLOOKUP($D16,รายชื่อผู้สมัคร!$A$4:$H$99,6,FALSE))) | G16: - | H16: =IF(G16="","",VLOOKUP(G16,Criteria!$D$2:$E$5,2,FALSE)) -> - | I16: - | J16: =IF(I16="","",VLOOKUP(I16,Criteria!$D$6:$E$9,2,FALSE)) -> - | K16: - | L16: =IF(K16="","",VLOOKUP(K16,Criteria!$D$10:$E$13,2,FALSE)) -> - | M16: - | N16: =IF(M16="","",VLOOKUP(M16,Criteria!$D$14:$E$21,2,FALSE)) -> - | O16: - | P16: =IF(O16="","",VLOOKUP(O16,Criteria!$D$22:$E$25,2,FALSE)) -> - | Q16: - | R16: =IF(Q16="","",VLOOKUP(Q16,Criteria!$D$26:$E$29,2,FALSE)) -> - | S16: - | T16: =IF(S16="","",VLOOKUP(S16,Criteria!$D$30:$E$33,2,FALSE)) -> - | U16: - | V16: =IF(U16="","",VLOOKUP(U16,Criteria!$D$34:$E$38,2,FALSE)) -> - | W16: - | X16: =IF(W16="","",VLOOKUP(W16,Criteria!$D$39:$E$42,2,FALSE)) -> - | Y16: - | Z16: =IF(Y16="","",VLOOKUP(Y16,Criteria!$D$43:$E$44,2,FALSE)) -> - | AA16: =SUM(H16,J16,L16,N16,P16,R16,T16,V16,X16,Z16) -> 0 | AB16: - | AC16: -
A17: มารดา อาชีพ | B17: =VLOOKUP($A$2,Data!$B$2:$AK$99874,23,FALSE) -> ธุรกิจส่วนตัว / ค้าขาย | E17: =IF($D17="","",VLOOKUP($D17,รายชื่อผู้สมัคร!$A$4:$H$99,2,FALSE)) | F17: =IF($D17="","",(VLOOKUP($D17,รายชื่อผู้สมัคร!$A$4:$H$99,4,FALSE) & " " & VLOOKUP($D17,รายชื่อผู้สมัคร!$A$4:$H$99,5,FALSE) & " " & VLOOKUP($D17,รายชื่อผู้สมัคร!$A$4:$H$99,6,FALSE))) | G17: - | H17: =IF(G17="","",VLOOKUP(G17,Criteria!$D$2:$E$5,2,FALSE)) -> - | I17: - | J17: =IF(I17="","",VLOOKUP(I17,Criteria!$D$6:$E$9,2,FALSE)) -> - | K17: - | L17: =IF(K17="","",VLOOKUP(K17,Criteria!$D$10:$E$13,2,FALSE)) -> - | M17: - | N17: =IF(M17="","",VLOOKUP(M17,Criteria!$D$14:$E$21,2,FALSE)) -> - | O17: - | P17: =IF(O17="","",VLOOKUP(O17,Criteria!$D$22:$E$25,2,FALSE)) -> - | Q17: - | R17: =IF(Q17="","",VLOOKUP(Q17,Criteria!$D$26:$E$29,2,FALSE)) -> - | S17: - | T17: =IF(S17="","",VLOOKUP(S17,Criteria!$D$30:$E$33,2,FALSE)) -> - | U17: - | V17: =IF(U17="","",VLOOKUP(U17,Criteria!$D$34:$E$38,2,FALSE)) -> - | W17: - | X17: =IF(W17="","",VLOOKUP(W17,Criteria!$D$39:$E$42,2,FALSE)) -> - | Y17: - | Z17: =IF(Y17="","",VLOOKUP(Y17,Criteria!$D$43:$E$44,2,FALSE)) -> - | AA17: =SUM(H17,J17,L17,N17,P17,R17,T17,V17,X17,Z17) -> 0 | AB17: - | AC17: -
A18: มารดา รายได้ | B18: =VLOOKUP($A$2,Data!$B$2:$AK$99874,24,FALSE) -> 10000 | E18: =IF($D18="","",VLOOKUP($D18,รายชื่อผู้สมัคร!$A$4:$H$99,2,FALSE)) | F18: =IF($D18="","",(VLOOKUP($D18,รายชื่อผู้สมัคร!$A$4:$H$99,4,FALSE) & " " & VLOOKUP($D18,รายชื่อผู้สมัคร!$A$4:$H$99,5,FALSE) & " " & VLOOKUP($D18,รายชื่อผู้สมัคร!$A$4:$H$99,6,FALSE))) | G18: - | H18: =IF(G18="","",VLOOKUP(G18,Criteria!$D$2:$E$5,2,FALSE)) -> - | I18: - | J18: =IF(I18="","",VLOOKUP(I18,Criteria!$D$6:$E$9,2,FALSE)) -> - | K18: - | L18: =IF(K18="","",VLOOKUP(K18,Criteria!$D$10:$E$13,2,FALSE)) -> - | M18: - | N18: =IF(M18="","",VLOOKUP(M18,Criteria!$D$14:$E$21,2,FALSE)) -> - | O18: - | P18: =IF(O18="","",VLOOKUP(O18,Criteria!$D$22:$E$25,2,FALSE)) -> - | Q18: - | R18: =IF(Q18="","",VLOOKUP(Q18,Criteria!$D$26:$E$29,2,FALSE)) -> - | S18: - | T18: =IF(S18="","",VLOOKUP(S18,Criteria!$D$30:$E$33,2,FALSE)) -> - | U18: - | V18: =IF(U18="","",VLOOKUP(U18,Criteria!$D$34:$E$38,2,FALSE)) -> - | W18: - | X18: =IF(W18="","",VLOOKUP(W18,Criteria!$D$39:$E$42,2,FALSE)) -> - | Y18: - | Z18: =IF(Y18="","",VLOOKUP(Y18,Criteria!$D$43:$E$44,2,FALSE)) -> - | AA18: =SUM(H18,J18,L18,N18,P18,R18,T18,V18,X18,Z18) -> 0 | AB18: - | AC18: -
A19: มารดา สภาพ | B19: =VLOOKUP($A$2,Data!$B$2:$AK$99874,25,FALSE) -> มีชีวิตอยู่ | E19: =IF($D19="","",VLOOKUP($D19,รายชื่อผู้สมัคร!$A$4:$H$99,2,FALSE)) | F19: =IF($D19="","",(VLOOKUP($D19,รายชื่อผู้สมัคร!$A$4:$H$99,4,FALSE) & " " & VLOOKUP($D19,รายชื่อผู้สมัคร!$A$4:$H$99,5,FALSE) & " " & VLOOKUP($D19,รายชื่อผู้สมัคร!$A$4:$H$99,6,FALSE))) | G19: - | H19: =IF(G19="","",VLOOKUP(G19,Criteria!$D$2:$E$5,2,FALSE)) -> - | I19: - | J19: =IF(I19="","",VLOOKUP(I19,Criteria!$D$6:$E$9,2,FALSE)) -> - | K19: - | L19: =IF(K19="","",VLOOKUP(K19,Criteria!$D$10:$E$13,2,FALSE)) -> - | M19: - | N19: =IF(M19="","",VLOOKUP(M19,Criteria!$D$14:$E$21,2,FALSE)) -> - | O19: - | P19: =IF(O19="","",VLOOKUP(O19,Criteria!$D$22:$E$25,2,FALSE)) -> - | Q19: - | R19: =IF(Q19="","",VLOOKUP(Q19,Criteria!$D$26:$E$29,2,FALSE)) -> - | S19: - | T19: =IF(S19="","",VLOOKUP(S19,Criteria!$D$30:$E$33,2,FALSE)) -> - | U19: - | V19: =IF(U19="","",VLOOKUP(U19,Criteria!$D$34:$E$38,2,FALSE)) -> - | W19: - | X19: =IF(W19="","",VLOOKUP(W19,Criteria!$D$39:$E$42,2,FALSE)) -> - | Y19: - | Z19: =IF(Y19="","",VLOOKUP(Y19,Criteria!$D$43:$E$44,2,FALSE)) -> - | AA19: =SUM(H19,J19,L19,N19,P19,R19,T19,V19,X19,Z19) -> 0 | AB19: - | AC19: -
A20: สภาพบิดา-มารดา | B20: =VLOOKUP($A$2,Data!$B$2:$AK$99874,26,FALSE) -> อยู่ด้วยกัน | E20: =IF($D20="","",VLOOKUP($D20,รายชื่อผู้สมัคร!$A$4:$H$99,2,FALSE)) | F20: =IF($D20="","",(VLOOKUP($D20,รายชื่อผู้สมัคร!$A$4:$H$99,4,FALSE) & " " & VLOOKUP($D20,รายชื่อผู้สมัคร!$A$4:$H$99,5,FALSE) & " " & VLOOKUP($D20,รายชื่อผู้สมัคร!$A$4:$H$99,6,FALSE))) | G20: - | H20: =IF(G20="","",VLOOKUP(G20,Criteria!$D$2:$E$5,2,FALSE)) -> - | I20: - | J20: =IF(I20="","",VLOOKUP(I20,Criteria!$D$6:$E$9,2,FALSE)) -> - | K20: - | L20: =IF(K20="","",VLOOKUP(K20,Criteria!$D$10:$E$13,2,FALSE)) -> - | M20: - | N20: =IF(M20="","",VLOOKUP(M20,Criteria!$D$14:$E$21,2,FALSE)) -> - | O20: - | P20: =IF(O20="","",VLOOKUP(O20,Criteria!$D$22:$E$25,2,FALSE)) -> - | Q20: - | R20: =IF(Q20="","",VLOOKUP(Q20,Criteria!$D$26:$E$29,2,FALSE)) -> - | S20: - | T20: =IF(S20="","",VLOOKUP(S20,Criteria!$D$30:$E$33,2,FALSE)) -> - | U20: - | V20: =IF(U20="","",VLOOKUP(U20,Criteria!$D$34:$E$38,2,FALSE)) -> - | W20: - | X20: =IF(W20="","",VLOOKUP(W20,Criteria!$D$39:$E$42,2,FALSE)) -> - | Y20: - | Z20: =IF(Y20="","",VLOOKUP(Y20,Criteria!$D$43:$E$44,2,FALSE)) -> - | AA20: =SUM(H20,J20,L20,N20,P20,R20,T20,V20,X20,Z20) -> 0 | AB20: - | AC20: -
A21: คนออกเงินเรียน | B21: =VLOOKUP($A$2,Data!$B$2:$AK$99874,27,FALSE) -> มารดา | E21: =IF($D21="","",VLOOKUP($D21,รายชื่อผู้สมัคร!$A$4:$H$99,2,FALSE)) | F21: =IF($D21="","",(VLOOKUP($D21,รายชื่อผู้สมัคร!$A$4:$H$99,4,FALSE) & " " & VLOOKUP($D21,รายชื่อผู้สมัคร!$A$4:$H$99,5,FALSE) & " " & VLOOKUP($D21,รายชื่อผู้สมัคร!$A$4:$H$99,6,FALSE))) | G21: - | H21: =IF(G21="","",VLOOKUP(G21,Criteria!$D$2:$E$5,2,FALSE)) -> - | I21: - | J21: =IF(I21="","",VLOOKUP(I21,Criteria!$D$6:$E$9,2,FALSE)) -> - | K21: - | L21: =IF(K21="","",VLOOKUP(K21,Criteria!$D$10:$E$13,2,FALSE)) -> - | M21: - | N21: =IF(M21="","",VLOOKUP(M21,Criteria!$D$14:$E$21,2,FALSE)) -> - | O21: - | P21: =IF(O21="","",VLOOKUP(O21,Criteria!$D$22:$E$25,2,FALSE)) -> - | Q21: - | R21: =IF(Q21="","",VLOOKUP(Q21,Criteria!$D$26:$E$29,2,FALSE)) -> - | S21: - | T21: =IF(S21="","",VLOOKUP(S21,Criteria!$D$30:$E$33,2,FALSE)) -> - | U21: - | V21: =IF(U21="","",VLOOKUP(U21,Criteria!$D$34:$E$38,2,FALSE)) -> - | W21: - | X21: =IF(W21="","",VLOOKUP(W21,Criteria!$D$39:$E$42,2,FALSE)) -> - | Y21: - | Z21: =IF(Y21="","",VLOOKUP(Y21,Criteria!$D$43:$E$44,2,FALSE)) -> - | AA21: =SUM(H21,J21,L21,N21,P21,R21,T21,V21,X21,Z21) -> 0 | AB21: - | AC21: -
A22: อุปการะ-ความเกี่ยวข้อง | B22: =VLOOKUP($A$2,Data!$B$2:$AK$99874,28,FALSE) -> 0 | E22: =IF($D22="","",VLOOKUP($D22,รายชื่อผู้สมัคร!$A$4:$H$99,2,FALSE)) | F22: =IF($D22="","",(VLOOKUP($D22,รายชื่อผู้สมัคร!$A$4:$H$99,4,FALSE) & " " & VLOOKUP($D22,รายชื่อผู้สมัคร!$A$4:$H$99,5,FALSE) & " " & VLOOKUP($D22,รายชื่อผู้สมัคร!$A$4:$H$99,6,FALSE))) | G22: - | H22: =IF(G22="","",VLOOKUP(G22,Criteria!$D$2:$E$5,2,FALSE)) -> - | I22: - | J22: =IF(I22="","",VLOOKUP(I22,Criteria!$D$6:$E$9,2,FALSE)) -> - | K22: - | L22: =IF(K22="","",VLOOKUP(K22,Criteria!$D$10:$E$13,2,FALSE)) -> - | M22: - | N22: =IF(M22="","",VLOOKUP(M22,Criteria!$D$14:$E$21,2,FALSE)) -> - | O22: - | P22: =IF(O22="","",VLOOKUP(O22,Criteria!$D$22:$E$25,2,FALSE)) -> - | Q22: - | R22: =IF(Q22="","",VLOOKUP(Q22,Criteria!$D$26:$E$29,2,FALSE)) -> - | S22: - | T22: =IF(S22="","",VLOOKUP(S22,Criteria!$D$30:$E$33,2,FALSE)) -> - | U22: - | V22: =IF(U22="","",VLOOKUP(U22,Criteria!$D$34:$E$38,2,FALSE)) -> - | W22: - | X22: =IF(W22="","",VLOOKUP(W22,Criteria!$D$39:$E$42,2,FALSE)) -> - | Y22: - | Z22: =IF(Y22="","",VLOOKUP(Y22,Criteria!$D$43:$E$44,2,FALSE)) -> - | AA22: =SUM(H22,J22,L22,N22,P22,R22,T22,V22,X22,Z22) -> 0 | AB22: - | AC22: -
A23: อุปการะ-อาชีพ | B23: =VLOOKUP($A$2,Data!$B$2:$AK$99874,29,FALSE) -> 0 | E23: =IF($D23="","",VLOOKUP($D23,รายชื่อผู้สมัคร!$A$4:$H$99,2,FALSE)) | F23: =IF($D23="","",(VLOOKUP($D23,รายชื่อผู้สมัคร!$A$4:$H$99,4,FALSE) & " " & VLOOKUP($D23,รายชื่อผู้สมัคร!$A$4:$H$99,5,FALSE) & " " & VLOOKUP($D23,รายชื่อผู้สมัคร!$A$4:$H$99,6,FALSE))) | G23: - | H23: =IF(G23="","",VLOOKUP(G23,Criteria!$D$2:$E$5,2,FALSE)) -> - | I23: - | J23: =IF(I23="","",VLOOKUP(I23,Criteria!$D$6:$E$9,2,FALSE)) -> - | K23: - | L23: =IF(K23="","",VLOOKUP(K23,Criteria!$D$10:$E$13,2,FALSE)) -> - | M23: - | N23: =IF(M23="","",VLOOKUP(M23,Criteria!$D$14:$E$21,2,FALSE)) -> - | O23: - | P23: =IF(O23="","",VLOOKUP(O23,Criteria!$D$22:$E$25,2,FALSE)) -> - | Q23: - | R23: =IF(Q23="","",VLOOKUP(Q23,Criteria!$D$26:$E$29,2,FALSE)) -> - | S23: - | T23: =IF(S23="","",VLOOKUP(S23,Criteria!$D$30:$E$33,2,FALSE)) -> - | U23: - | V23: =IF(U23="","",VLOOKUP(U23,Criteria!$D$34:$E$38,2,FALSE)) -> - | W23: - | X23: =IF(W23="","",VLOOKUP(W23,Criteria!$D$39:$E$42,2,FALSE)) -> - | Y23: - | Z23: =IF(Y23="","",VLOOKUP(Y23,Criteria!$D$43:$E$44,2,FALSE)) -> - | AA23: =SUM(H23,J23,L23,N23,P23,R23,T23,V23,X23,Z23) -> 0 | AB23: - | AC23: -
A24: อุปการะ-รายได้ | B24: =VLOOKUP($A$2,Data!$B$2:$AK$99874,30,FALSE) -> 0 | E24: =IF($D24="","",VLOOKUP($D24,รายชื่อผู้สมัคร!$A$4:$H$99,2,FALSE)) | F24: =IF($D24="","",(VLOOKUP($D24,รายชื่อผู้สมัคร!$A$4:$H$99,4,FALSE) & " " & VLOOKUP($D24,รายชื่อผู้สมัคร!$A$4:$H$99,5,FALSE) & " " & VLOOKUP($D24,รายชื่อผู้สมัคร!$A$4:$H$99,6,FALSE))) | G24: - | H24: =IF(G24="","",VLOOKUP(G24,Criteria!$D$2:$E$5,2,FALSE)) -> - | I24: - | J24: =IF(I24="","",VLOOKUP(I24,Criteria!$D$6:$E$9,2,FALSE)) -> - | K24: - | L24: =IF(K24="","",VLOOKUP(K24,Criteria!$D$10:$E$13,2,FALSE)) -> - | M24: - | N24: =IF(M24="","",VLOOKUP(M24,Criteria!$D$14:$E$21,2,FALSE)) -> - | O24: - | P24: =IF(O24="","",VLOOKUP(O24,Criteria!$D$22:$E$25,2,FALSE)) -> - | Q24: - | R24: =IF(Q24="","",VLOOKUP(Q24,Criteria!$D$26:$E$29,2,FALSE)) -> - | S24: - | T24: =IF(S24="","",VLOOKUP(S24,Criteria!$D$30:$E$33,2,FALSE)) -> - | U24: - | V24: =IF(U24="","",VLOOKUP(U24,Criteria!$D$34:$E$38,2,FALSE)) -> - | W24: - | X24: =IF(W24="","",VLOOKUP(W24,Criteria!$D$39:$E$42,2,FALSE)) -> - | Y24: - | Z24: =IF(Y24="","",VLOOKUP(Y24,Criteria!$D$43:$E$44,2,FALSE)) -> - | AA24: =SUM(H24,J24,L24,N24,P24,R24,T24,V24,X24,Z24) -> 0 | AB24: - | AC24: -
A25: พี่น้อง-ทำงาน | B25: =VLOOKUP($A$2,Data!$B$2:$AK$99874,31,FALSE) -> 0 | E25: =IF($D25="","",VLOOKUP($D25,รายชื่อผู้สมัคร!$A$4:$H$99,2,FALSE)) | F25: =IF($D25="","",(VLOOKUP($D25,รายชื่อผู้สมัคร!$A$4:$H$99,4,FALSE) & " " & VLOOKUP($D25,รายชื่อผู้สมัคร!$A$4:$H$99,5,FALSE) & " " & VLOOKUP($D25,รายชื่อผู้สมัคร!$A$4:$H$99,6,FALSE))) | G25: - | H25: =IF(G25="","",VLOOKUP(G25,Criteria!$D$2:$E$5,2,FALSE)) -> - | I25: - | J25: =IF(I25="","",VLOOKUP(I25,Criteria!$D$6:$E$9,2,FALSE)) -> - | K25: - | L25: =IF(K25="","",VLOOKUP(K25,Criteria!$D$10:$E$13,2,FALSE)) -> - | M25: - | N25: =IF(M25="","",VLOOKUP(M25,Criteria!$D$14:$E$21,2,FALSE)) -> - | O25: - | P25: =IF(O25="","",VLOOKUP(O25,Criteria!$D$22:$E$25,2,FALSE)) -> - | Q25: - | R25: =IF(Q25="","",VLOOKUP(Q25,Criteria!$D$26:$E$29,2,FALSE)) -> - | S25: - | T25: =IF(S25="","",VLOOKUP(S25,Criteria!$D$30:$E$33,2,FALSE)) -> - | U25: - | V25: =IF(U25="","",VLOOKUP(U25,Criteria!$D$34:$E$38,2,FALSE)) -> - | W25: - | X25: =IF(W25="","",VLOOKUP(W25,Criteria!$D$39:$E$42,2,FALSE)) -> - | Y25: - | Z25: =IF(Y25="","",VLOOKUP(Y25,Criteria!$D$43:$E$44,2,FALSE)) -> - | AA25: =SUM(H25,J25,L25,N25,P25,R25,T25,V25,X25,Z25) -> 0 | AB25: - | AC25: -
A26: พี่น้อง-ไม่ทำงาน | B26: =VLOOKUP($A$2,Data!$B$2:$AK$99874,32,FALSE) -> 0 | E26: =IF($D26="","",VLOOKUP($D26,รายชื่อผู้สมัคร!$A$4:$H$99,2,FALSE)) | F26: =IF($D26="","",(VLOOKUP($D26,รายชื่อผู้สมัคร!$A$4:$H$99,4,FALSE) & " " & VLOOKUP($D26,รายชื่อผู้สมัคร!$A$4:$H$99,5,FALSE) & " " & VLOOKUP($D26,รายชื่อผู้สมัคร!$A$4:$H$99,6,FALSE))) | G26: - | H26: =IF(G26="","",VLOOKUP(G26,Criteria!$D$2:$E$5,2,FALSE)) -> - | I26: - | J26: =IF(I26="","",VLOOKUP(I26,Criteria!$D$6:$E$9,2,FALSE)) -> - | K26: - | L26: =IF(K26="","",VLOOKUP(K26,Criteria!$D$10:$E$13,2,FALSE)) -> - | M26: - | N26: =IF(M26="","",VLOOKUP(M26,Criteria!$D$14:$E$21,2,FALSE)) -> - | O26: - | P26: =IF(O26="","",VLOOKUP(O26,Criteria!$D$22:$E$25,2,FALSE)) -> - | Q26: - | R26: =IF(Q26="","",VLOOKUP(Q26,Criteria!$D$26:$E$29,2,FALSE)) -> - | S26: - | T26: =IF(S26="","",VLOOKUP(S26,Criteria!$D$30:$E$33,2,FALSE)) -> - | U26: - | V26: =IF(U26="","",VLOOKUP(U26,Criteria!$D$34:$E$38,2,FALSE)) -> - | W26: - | X26: =IF(W26="","",VLOOKUP(W26,Criteria!$D$39:$E$42,2,FALSE)) -> - | Y26: - | Z26: =IF(Y26="","",VLOOKUP(Y26,Criteria!$D$43:$E$44,2,FALSE)) -> - | AA26: =SUM(H26,J26,L26,N26,P26,R26,T26,V26,X26,Z26) -> 0 | AB26: - | AC26: -
A27: พี่น้อง-เรียน | B27: =VLOOKUP($A$2,Data!$B$2:$AK$99874,33,FALSE) -> 0 | E27: =IF($D27="","",VLOOKUP($D27,รายชื่อผู้สมัคร!$A$4:$H$99,2,FALSE)) | F27: =IF($D27="","",(VLOOKUP($D27,รายชื่อผู้สมัคร!$A$4:$H$99,4,FALSE) & " " & VLOOKUP($D27,รายชื่อผู้สมัคร!$A$4:$H$99,5,FALSE) & " " & VLOOKUP($D27,รายชื่อผู้สมัคร!$A$4:$H$99,6,FALSE))) | G27: - | H27: =IF(G27="","",VLOOKUP(G27,Criteria!$D$2:$E$5,2,FALSE)) -> - | I27: - | J27: =IF(I27="","",VLOOKUP(I27,Criteria!$D$6:$E$9,2,FALSE)) -> - | K27: - | L27: =IF(K27="","",VLOOKUP(K27,Criteria!$D$10:$E$13,2,FALSE)) -> - | M27: - | N27: =IF(M27="","",VLOOKUP(M27,Criteria!$D$14:$E$21,2,FALSE)) -> - | O27: - | P27: =IF(O27="","",VLOOKUP(O27,Criteria!$D$22:$E$25,2,FALSE)) -> - | Q27: - | R27: =IF(Q27="","",VLOOKUP(Q27,Criteria!$D$26:$E$29,2,FALSE)) -> - | S27: - | T27: =IF(S27="","",VLOOKUP(S27,Criteria!$D$30:$E$33,2,FALSE)) -> - | U27: - | V27: =IF(U27="","",VLOOKUP(U27,Criteria!$D$34:$E$38,2,FALSE)) -> - | W27: - | X27: =IF(W27="","",VLOOKUP(W27,Criteria!$D$39:$E$42,2,FALSE)) -> - | Y27: - | Z27: =IF(Y27="","",VLOOKUP(Y27,Criteria!$D$43:$E$44,2,FALSE)) -> - | AA27: =SUM(H27,J27,L27,N27,P27,R27,T27,V27,X27,Z27) -> 0 | AB27: - | AC27: -
A28: กยศ | B28: =VLOOKUP($A$2,Data!$B$2:$AK$99874,34,FALSE) -> 0
A29: ทุน | B29: =VLOOKUP($A$2,Data!$B$2:$AK$99874,35,FALSE) -> -2568 ทุนการศึกษาคณะวิศวกรรมศาสตร์ : 5,000
A32: GPA | B32: =VLOOKUP($A$2,Data!$B$2:$AK$99874,9,FALSE) -> 4

Sheet Criteria
A1: No. | B1: หัวข้อประเมิน | D1: เกณฑ์การให้คะแนน | E1: คะแนน | F1: คะแนนรวม
A2: 1 | B2: ค่าเทอม | D2: ไม่มีผู้อื่นส่งเสียค่าเทอม | E2: 10 | F2: 10
D3: มีผู้อื่นหรือแหล่งทุนอื่นส่งเสียค่าเทอมบางส่วน หรือกู้ยืม หรือกู้ กยศ ไม่ผ่าน | E3: 5
D4: มีผู้อื่นส่งเสียค่าเทอมทั้งหมด | E4: 0
D5: - | E5: -
A6: 2 | B6: ค่าใช้จ่ายประจำวัน | D6: ไม่มีผู้อื่นส่งเสียค่าใช้จ่ายประจำวัน | E6: 10 | F6: 10
D7: มีผู้อื่นหรือแหล่งทุนอื่นส่งเสียค่าใช้จ่ายประจำวัน แต่ไม่เพียงพอ หรือได้รับจากการกู้ยืม | E7: 5
D8: มีผู้อื่นส่งเสียค่าใช้จ่ายประจำวันอย่างเพียงพอ | E8: 0
D9: - | E9: -
A10: 3 | B10: ทำงานพิเศษ | D10: ปัจจุบันทำงานหาเลี้ยงตนเอง หรือทำงานที่ไม่ได้มีรายรับ | E10: 10 | F10: 10
D11: เคยทำงานพิเศษ กำลังมองหางานพิเศษ หรือมีเหตุอันควรให้ไม่สามารถทำงานพิเศษได้ | E11: 5
D12: ไม่ทำงานหาเลี้ยงตนเอง | E12: 0
D13: - | E13: -
A14: 4 | B14: การนำทุนไปใช้ประโยชน์ | D14: ใช้เป็นค่าเทอม หรือค่าใช้จ่ายประจำวัน | E14: 20 | F14: 20
D15: ค่าเทอม หรือค่าใช้จ่าย เพิ่มจากที่ได้จากผู้อื่นหรือแหล่งทุนอื่น | E15: 15
D16: ชำระหนี้สิน เงินกู้ยืมมาจ่ายค่าเทอม ค่ากินอยู่ หรือต้องส่งเสียครอบครัว | E16: 10
D17: ซื้ออุปกรณ์การเรียนที่ขาดแคลน | E17: 5
D18: เงินสะสมฉุกเฉิน หรือ ไม่อยากรบกวนครอบครัว | E18: 5
D19: พัฒนาทักษะเพิ่มเติม ซื้ออุปกรณ์การเรียนเพิ่มเติม ค่าใช้จ่ายเพิ่มเติมจากสหกิจ | E19: 5
D20: อื่นๆที่จำเป็น | E20: 5
D21: - | E21: -
A22: 5 | B22: ค่าใช้จ่ายประจำวัน | C22: 0 | D22: ≤ 5,000 บาท ต่อเดือน | E22: 10 | F22: 10
C23: 151 | D23: อยู่ระหว่าง 5,000 - 10,000 บาท ต่อเดือน | E23: 5
C24: 300 | D24: มากกว่า 10,000 บาทต่อเดือน | E24: 0
D25: - | E25: -
A26: 6 | B26: ค่าที่พัก (ค่าเช่า ค่าน้ำ ค่าไฟ) | D26: หอในมหาวิทยาลัย นอนวัด หรือ ค่าเช่าต่ำกว่า 2000 ต่อเดือน | E26: 10 | F26: 10
D27: พักอยู่กับครอบครัว ญาติ หรือ ค่าที่พักอยู่ระหว่าง 2001-4000 บาท | E27: 5
D28: ค่าที่พักมากกว่า 4000 บาท | E28: 0
D29: - | E29: -
A30: 7 | B30: การเดินทางมาเรียน | D30: รถสาธารณะ/รถจักรยาน/เดิน/ติดรถผู้อื่นมา | E30: 5 | F30: 5
D31: รถมอเตอร์ไซค์ | E31: 2
D32: รถยนต์ หรือ รถรับส่งเอกชน (Grab) | E32: 0
D33: - | E33: -
A34: 8 | B34: ผลการเรียน | C34: 3 | D34: 3.00 ขึ้นไป | E34: 5 | F34: 5
C35: 2.5 | D35: 2.50-2.99 | E35: 3
C36: 2 | D36: 2.00-2.49 | E36: 1
C37: 0 | D37: ต่ำกว่า 2.00 | E37: 0
D38: - | E38: -
A39: 9 | B39: ดุลพินิจของอาจารย์ (0-10) | D39: จำเป็นมาก เช่น ประสบอุบัติเหตุร้ายแรง อุบัติภัย ผู้อุปการะเจ็บป่วย ล้มละลาย ฯลฯ | E39: 10 | F39: 10
D40: จำเป็นอื่นๆตามความเห็นอาจารย์ | E40: 5
...

Sheet Data
A1: 1 | B1: 2 | C1: 3 | D1: 4 | E1: 5 | F1: 6 | G1: 7 | H1: 8 | I1: 9 | J1: 10 | K1: 11 | L1: 12 | M1: 13 | N1: 14 | O1: 15 | P1: 16 | Q1: 17 | R1: 18 | S1: 19 | T1: 20 | U1: 21 | V1: 22 | W1: 23 | X1: 24 | Y1: 25 | Z1: 26 | AA1: 27 | AB1: 28 | AC1: 29 | AD1: 30 | AE1: 31 | AF1: 32 | AG1: 33 | AH1: 34 | AI1: 35 | AJ1: 36 | AK1: 37 | AL1: 38
A2: ลำดับ | B2: รหัส | C2: คำนำหน้า | D2: ชือ | E2: สกุล | F2: คณะ | G2: สาขา | H2: ชั้นปี | I2: วันที่สมัคร | J2: gpa | K2: โทรศัพท์ | L2: อีเมล์ | M2: ที่พัก | N2: ค่าเช่าหอ/บ้าน รวมค่าน้ำ-ไฟ | O2: ค่าใช้จ่ายส่วนตัว | P2: ค่าอุปกรณ์การศึกษา | Q2: อุปกรณ์อิเล็กทรอนิกส์ที่มี | R2: รายได้เสริม | S2: บิดา อายุ | T2: บิดา อาชีพ | U2: บิดา รายได้ | V2: บิดา สภาพ | W2: มารดา อายุ | X2: มารดา อาชีพ | Y2: มารดา รายได้ | Z2: มารดา สภาพ | AA2: สภาพบิดา-มารดา | AB2: คนออกเงินเรียน | AC2: อุปการะ-ความเกี่ยวข้อง | AD2: อุปการะ-อาชีพ | AE2: อุปการะ-รายได้ | AF2: พี่น้อง-ทำงาน | AG2: พี่น้อง-ไม่ทำงาน | AH2: พี่น้อง-เรียน | AI2: กยศ | AJ2: ทุน | AL2: CITIZENID
A3: 1 | B3: 683040000-1 | C3: นาย | D3: aaa | E3: aaaa | F3: คณะวิศวกรรมศาสตร์ | G3: วิศวกรรมอุตสาหการ | H3: 1 | I3: 25/12/2568 15:03 | J3: 3.02 | K3: 810000001 | L3: aaa@kkumail.com | M3: หอพัก มข | N3: 940 | O3: 6000 | P3: 2000 | Q3: ไอแพดและโทรศัพท์มือถือ | R3: ไม่มีรายได้เสริม | T3: พนักงานเอกชน / ลูกจ้าง | U3: 9990 | V3: มีชีวิตอยู่ | X3: พนักงานเอกชน / ลูกจ้าง | Y3: 22666 | Z3: มีชีวิตอยู่ | AA3: อยู่ด้วยกัน | AB3: บิดา-มารดา | AI3: -2568 : 40,000 | AJ3: -2568 ทุนการศึกษาประเภท ข ภาคการศึกษาตอนต้น : 10,000 | AK3: https://maps.app.goo.gl/4iM5zfDSZf5jX7WZA | AL3: 1410100000001
A4: 2 | B4: 683040000-2 | C4: นาย | D4: bbb | E4: vvvv | F4: คณะวิศวกรรมศาสตร์ | G4: วิศวกรรมอุตสาหการ | H4: 1 | I4: 244146.6 | J4: 2.55 | K4: 810000001 | L4: aaa@kkumail.com | M4: บ้านบิดา/มารดา | N4: 2000 | O4: 4000 | P4: 500 | Q4: โทรศัพท์ ipad | R4: ไม่มีรายได้เสริม | T4: พนักงานเอกชน / ลูกจ้าง | V4: ถึงแก่กรรม | W4: 43 | X4: พนักงานเอกชน / ลูกจ้าง | Y4: 12000 | Z4: มีชีวิตอยู่ | AA4: บิดาถึงแก่กรรม | AB4: มารดา | AG4: 1 | AH4: 1 | AI4: -2568 : 28,000 | AJ4: -1 ทุนประเภท ข : 10,000 | AK4: https://maps.app.goo.gl/4iM5zfDSZf5jX7WZA | AL4: 1410100000002
A5: 3 | B5: 683040000-3 | C5: นาย | D5: ccc | E5: cccc | F5: คณะวิศวกรรมศาสตร์ | G5: วิศวกรรมเคมี | H5: 1 | I5: 15/11/2568 19:34 | J5: 1.66 | K5: 810000001 | L5: aaa@kkumail.com | M5: อื่นๆ | N5: 5000 | O5: 3000 | P5: 500 | Q5: โทรศัพท์ | R5: ไม่มีรายได้เสริม | S5: 46 | T5: พนักงานเอกชน / ลูกจ้าง | U5: 10000 | V5: มีชีวิตอยู่ | W5: 41 | X5: พนักงานเอกชน / ลูกจ้าง | Y5: 10000 | Z5: มีชีวิตอยู่ | AA5: อยู่ด้วยกัน | AB5: บิดา-มารดา | AH5: 1 | AK5: https://maps.app.goo.gl/4iM5zfDSZf5jX7WZA | AL5: 1410100000003
A6: 4 | B6: 683040000-4 | C6: นางสาว | D6: ddd | E6: dddd | F6: คณะวิศวกรรมศาสตร์ | G6: วิศวกรรมไฟฟ้า | H6: 1 | I6: 31/12/2568 16:17 | J6: 4 | K6: 810000001 | L6: aaa@kkumail.com | M6: อื่นๆ | N6: 2200 | O6: 3500 | P6: 500 | Q6: โทรศัพท์, iPad | R6: มีรายได้เสริม | S6: 71 | T6: ไม่ได้ประกอบอาชีพ | V6: มีชีวิตอยู่ | W6: 54 | X6: ธุรกิจส่วนตัว / ค้าขาย | Y6: 10000 | Z6: มีชีวิตอยู่ | AA6: อยู่ด้วยกัน | AB6: มารดา | AJ6: -2568 ทุนการศึกษาคณะวิศวกรรมศาสตร์ : 5,000 | AK6: https://maps.app.goo.gl/4iM5zfDSZf5jX7WZA | AL6: 1410100000004
A7: 5 | B7: 683040000-5 | C7: นางสาว | D7: eee | E7: eeee | F7: คณะวิศวกรรมศาสตร์ | G7: วิศวกรรมไฟฟ้า | H7: 1 | I7: 31/12/2568 11:58 | J7: 3.43 | K7: 810000001 | L7: aaa@kkumail.com | M7: อื่นๆ | N7: 2500 | O7: 3000 | Q7: 2 | R7: ไม่มีรายได้เสริม | S7: 49 | T7: พนักงานเอกชน / ลูกจ้าง | U7: 6000 | V7: มีชีวิตอยู่ | W7: 53 | X7: ไม่ได้ประกอบอาชีพ | Z7: มีชีวิตอยู่ | AA7: อยู่ด้วยกัน | AB7: บิดา-มารดา | AH7: 1 | AI7: -21,800 : | AJ7: -1 ทุน ข คณะวิศวกรรมศาสตร์ : 10,000 | AK7: https://maps.app.goo.gl/4iM5zfDSZf5jX7WZA | AL7: 1410100000005
A8: *

Sheet รายชื่อผู้สมัคร
A1: รายชื่อผู้สมัคร
A3: ลำดับ | B3: รหัส | C3: ลำดับ | D3: คำนำหน้า | E3: ชือ | F3: สกุล | G3: สาขา | H3: ชั้นปี
A4: 1 | B4: 683040000-1 | C4: 1 | D4: นาย | E4: aaa | F4: aaaa | G4: วิศวกรรมอุตสาหการ | H4: 1
A5: 2 | B5: 683040000-2 | C5: 2 | D5: นาย | E5: bbb | F5: vvvv | G5: วิศวกรรมอุตสาหการ | H5: 1
A6: 3 | B6: 683040000-3 | C6: 3 | D6: นาย | E6: ccc | F6: cccc | G6: วิศวกรรมเคมี | H6: 1
A7: 4 | B7: 683040000-4 | C7: 4 | D7: นางสาว | E7: ddd | F7: dddd | G7: วิศวกรรมไฟฟ้า | H7: 1
A8: 5 | B8: 683040000-5 | C8: 5 | D8: นางสาว | E8: eee | F8: eeee | G8: วิศวกรรมไฟฟ้า | H8: 1
